<mujoco>
    <option gravity="0 0 -9.81" timestep="0.01" /> <!-- integrator="implicit" /> -->

    <asset>
        <material name="blue" rgba="0 0 1 1" />
        <material name="green" rgba="0 1 0 1" />
        <material name="red" rgba="1 0 0 1" />
        <material name="white" rgba="1 1 1 1" />
        <texture type="skybox" builtin="gradient" rgb1="0.3 0.5 0.7" rgb2="0 0 0" width="512" height="3072" />
        <texture type="2d" name="groundplane" builtin="checker" rgb1="0.2 0.3 0.4" rgb2="0.1 0.2 0.3" markrgb="0.8 0.8 0.8" width="300" height="300" />
        <material name="groundplane" texture="groundplane" texuniform="true" texrepeat="5 5" reflectance="0.2" />
    </asset>

    <worldbody>
        <!-- <camera target="link_1" pos="-4 -4 3" euler="0 -45 -90" mode="trackcom" /> -->
        <geom name="floor" pos="0 0 -2.5" size="0 0 0.05" type="plane" material="groundplane" />
        <light diffuse=".5 .5 .5" pos="0 0 3" dir="0 0 -1" />

        <body name="link_1" pos="0 0 0" euler="90 0 0">
            <site name="site_1" type="cylinder" size=".05 .1" pos=" 0 0 0" euler="0 90 0" />
            <joint name="hinge_1" type="hinge" axis="1 0 0" />
            <geom name="g_link_1" type="cylinder" size=".1 .5" pos="0 0 .5" euler="0 0 0" material="red" mass="1" />
            <site name="site_2" type="cylinder" size=".05 .1" pos=" 0 0 1" euler="0 90 0" />
            <body name="link_2" pos=".2 0 1" euler="0 0 0">
                <joint name="hinge_2" type="hinge" axis="1 0 0" />
                <geom name="g_link_2" type="cylinder" size=".1 .5" pos="0 0 .5" euler="0 0 0" material="green" mass="1" />
                <site name="site_3" type="cylinder" size=".05 .1" pos="0 0 1" euler="0 90 0" />
                <body name="link_3" pos=".2 0 1" euler="0 0 0">
                    <joint name="hinge_3" type="hinge" axis="1 0 0" />
                    <geom name="g_link_3" type="cylinder" size=".1 .5" pos="0 0 .5" euler="0 0 0" material="blue" mass="1" />
                    <geom name="end_mass" type="sphere" size=".25" pos="0 0 1" euler="0 0 0" material="blue" mass="1" />
                </body>
            </body>
        </body>


        <body name="link_1_1" pos="1 0 0" euler="90 0 0">
            <site name="site_1_1" type="cylinder" size=".05 .1" pos=" 0 0 0" euler="0 90 0" />
            <joint name="free_1_1" type="free" />
            <geom name="g_link_1_1" type="cylinder" size=".1 .5" pos="0 0 .5" euler="0 0 0" material="red" mass="1" />
            <site name="site_2_1" type="cylinder" size=".05 .1" pos=" 0 0 1" euler="0 90 0" />
            <body name="link_2_1" pos=".2 0 1" euler="0 0 0">
                <joint name="hinge_2_1" type="hinge" axis="1 0 0" damping="100" />
                <geom name="g_link_2_1" type="cylinder" size=".1 .5" pos="0 0 .5" euler="0 0 0" material="green" mass="1" />
                <site name="site_3_1" type="cylinder" size=".05 .1" pos="0 0 1" euler="0 90 0" />
                <body name="link_3_1" pos=".2 0 1" euler="0 0 0">
                    <joint name="hinge_3_1" type="hinge" axis="1 0 0" damping="100" />
                    <geom name="g_link_3_1" type="cylinder" size=".1 .5" pos="0 0 .5" euler="0 0 0" material="blue" mass="1" />
                    <geom name="end_mass_1" type="sphere" size=".25" pos="0 0 1" euler="0 0 0" material="blue" mass="1" />
                </body>
            </body>
        </body>

        <body name="my_floating_body" pos=".5 -3 2">
            <!-- <joint name="box_free_j" type="slide" axis="0 0 1" /> -->
            <joint name="box_free_j" type="free" />
            <geom type="box" size="1 1 1" mass="50" />
        </body>

    </worldbody>
    <actuator>
        <position name="pos_servo_1" joint="hinge_1" kp="1" />
        <position name="pos_servo_2" joint="hinge_2" kp="1" />
        <position name="pos_servo_3" joint="hinge_3" kp="1" />

        <position name="pos_servo_2_1" joint="hinge_2_1" kp="1" />
        <position name="pos_servo_3_1" joint="hinge_3_1" kp="1" />
    </actuator>
    <sensor>
        <jointpos name="pos_sensor_1" joint="hinge_1" />
        <jointpos name="pos_sensor_2" joint="hinge_2" />
        <jointpos name="pos_sensor_3" joint="hinge_3" />

        <jointpos name="pos_sensor_2_1" joint="hinge_2_1" />
        <jointpos name="pos_sensor_3_1" joint="hinge_3_1" />
    </sensor>
</mujoco>